Workbook

Sheet Léeme
A1: Inventario-Fotosíntesis · SOT Limpia
A2: Fuente única de verdad del inventario para la app Fotosíntesis. Generada consolidando
A3: Legacy + Convex + ModeloPrecios + Caja + Ventas + Kardex (reconciliación Sintesis).
A5: PESTAÑAS
A6: • Inventario — 1 fila por ítem (A–AP = esquema canónico de la app; AQ–AU = ayudas).
A7: • Lotes — catálogo de lotes (incluye 31 recuperados). mostrarComoLote=Sí → se vende como 1 card.
A8: • Sublotes — grupos curados de ítems que se venden juntos (subconjunto de un lote).
A9: • Proveedores / Clientes / Ventas — catálogos y transacciones.
A10: • Calidades — lista canónica + factor de precio (referencia).
A11: • Listas — fuente de los menús desplegables (no borrar).
A13: COLUMNAS CLAVE
A14: • Peso (ct) D — quilates (numérico). Peso (gr) AQ — gramos de joya (numérico).
... A30: • Ver columna 'Notas / conflictos' por ítem para banderas.

Sheet Inventario
A1: Item | B1: FECHA INGRESO INVENTARIO | C1: Nombre | D1: Peso (ct) | E1: Color | F1: Calidad | G1: Cant. | H1: Talla | I1: Medidas | J1: Medidas (valores) | K1: Categoría | L1: costoBaseCOP | M1: precioEmbajadorCOP | N1: precioConscienteCOP | O1: UBICACIÓN | P1: ASESOR | Q1: ESTADO | R1: QR | S1: Colección | T1: CAJA | U1: preponderancia | V1: ASESOR ACTUAL | W1: ESTADO ASESOR | X1: loteId | Y1: mostrarEnCatalogo | Z1: procedencia | AA1: observacion | AB1: rendimientoEsperado | AC1: cantidadEstimada | AD1: nivelRareza | AE1: calificacion | AF1: tipoEsmeralda | AG1: subtipoForm | AH1: tipoJoya | AI1: tecnicaJoya | AJ1: minerales | AK1: complementos | AL1: fotoUrl | AM1: certificadoUrl | AN1: formulaGema | AO1: formulaJoya | AP1: rangoDescuento | AQ1: Peso (gr) | AR1: Costo lote (fórmula) | AS1: Precio x2.6 (fórmula) | AT1: Precio objetivo (modelo) | AU1: Caja: precio venta | AV1: Caja: valor pagado | AW1: Caja: saldo | AX1: Caja: comprador | AY1: Caja: estado contable | AZ1: subLote (grupo) | BA1: Producto (URL) | BB1: Carpeta fotos (Drive) | BC1: Anima: notas relacionadas | BD1: Fuentes | BE1: Notas / conflictos
A2: 1 | B2: 31-oct-2025 | C2: Rey Midas | D2: 1.47 | E2: Verde Natural | F2: COMERCIAL FINA | G2: 1 | H2: Esmeralda | K2: Gema | L2: 244231 | O2: ASESOR | P2: M.Campuzano | Q2: VENDIDA | R2: https://tierramadre.app/p/1 | S2: #4000 | T2: Legalizada | AR2: =IFERROR(VLOOKUP($X2,Lotes!$A:$E,5,FALSE())*$U2,"") | AS2: =IF($L2="","",$L2*2.6) -> 635000.6 | AU2: 635000 | AV2: 635000 | AW2: 0 | AX2: M.Campuzano | AY2: VENDIDO | BA2: https://tierramadre.app/product/1 | BB2: https://drive.google.com/drive/folders/194ctZBJ3jKBQrP1k6LbqwYAwxxY9Y-Zo | BC2: 2026-07-18-rey-midas-item-1 | BD2: Legacy + Fotosintesis/Convex + CajaInventario | BE2: costo estimado = precio/2.6 (costo original igualaba al precio)
A3: 2 | B3: 31-oct-2025 | C3: Las Niñas | D3: 0.43 | E3: Verde Natural | F3: COMERCIAL FINA | G3: 2 | H3: Redonda | K3: Gema | L3: 71154 | O3: ASESOR | P3: M.Echeverry | Q3: VENDIDA | R3: https://tierramadre.app/p/2 | S3: #4000 | T3: Legalizada | AR3: =IFERROR(VLOOKUP($X3,Lotes!$A:$E,5,FALSE())*$U3,"") | AS3: =IF($L3="","",$L3*2.6) -> 185000.4 | AU3: 185000 | AV3: 185000 | AW3: 0 | AX3: M.Echeverry | AY3: VENDIDO | BA3: https://tierramadre.app/product/2 | BB3: https://drive.google.com/drive/folders/1f0pQmqKCoH27iYLaGLojrxNoIMKSGH5a | BC3: 2026-07-18-las-ninas-item-2 | BD3: Legacy + Fotosintesis/Convex + CajaInventario | BE3: costo estimado = precio/2.6 (costo original igualaba al precio)
A4: 3 | B4: 31-oct-2025 | C4: Las Margaritas | D4: 1.36 | E4: Verde Natural | F4: COMERCIAL FINA | G4: 2 | H4: Esmeralda | K4: Gema | L4: 113077 | O4: EMBAJADOR | P4: Isa la Negra Vikinga Warrior Portocarrero | Q4: VENDIDA | R4: https://tierramadre.app/p/3 | S4: #4000 | T4: Pte Fecha x Legalizar | AR4: =IFERROR(VLOOKUP($X4,Lotes!$A:$E,5,FALSE())*$U4,"") | AS4: =IF($L4="","",$L4*2.6) -> 294000.2 | AU4: 294000 | AV4: 294000 | AW4: 294000 | AX4: Isa la Negra Vikinga Warrior Portocarrero | AY4: CARTERA | BA4: https://tierramadre.app/product/3 | BB4: https://drive.google.com/drive/folders/1kXononMMYnH_6D8ogQMy0uy7CpaDSwKF | BC4: 2026-07-18-las-margaritas-item-3 | BD4: Legacy + Fotosintesis/Convex + CajaInventario | BE4: costo estimado = precio/2.6 (costo original igualaba al precio)
A5: 4 | B5: 31-oct-2025 | C5: Los Robles | D5: 1.56 | E5: Verde Natural | F5: COMERCIAL FINA | G5: 2 | H5: Esmeralda | K5: Gema | L5: 259231 | O5: ASESOR | P5: A.Molano | Q5: VENDIDA | R5: https://tierramadre.app/p/4 | S5: #4000 | T5: Legalizada | AR5: =IFERROR(VLOOKUP($X5,Lotes!$A:$E,5,FALSE())*$U5,"") | AS5: =IF($L5="","",$L5*2.6) -> 674000.6 | AU5: 674000 | AV5: 606600 | AW5: 0 | AX5: A.Molano | AY5: VENDIDO | BA5: https://tierramadre.app/product/4 | BB5: https://drive.google.com/drive/folders/1ct_fayajbdnGYyepO4WvlxzzD2mYuePw | BC5: 2026-07-18-los-robles-item-4 | BD5: Legacy + Fotosintesis/Convex + CajaInventario | BE5: costo estimado = precio/2.6 (costo original igualaba al precio)
A6: 5 | B6: 31-oct-2025 | C6: Los Tulipanes | D6: 1.26 | E6: Verde Natural | F6: COMERCIAL SUPERIOR | G6: 2 | H6: Cuadrada | K6: Gema | L6: 191923 | O6: ASESOR | P6: M.Gómez | Q6: VENDIDA | R6: https://tierramadre.app/p/5 | S6: #4000 | T6: Legalizada | AR6: =IFERROR(VLOOKUP($X6,Lotes!$A:$E,5,FALSE())*$U6,"") | AS6: =IF($L6="","",$L6*2.6) -> 498999.8 | AU6: 499000 | AV6: 499000 | AW6: 0 | AX6: M.Gomez | AY6: VENDIDO | BA6: https://tierramadre.app/product/5 | BB6: https://drive.google.com/drive/folders/1Ml10tLHgct3VB2RqrRLx-wKYVONJty1R | BC6: 2026-07-18-los-tulipanes-item-5 | BD6: Legacy + Fotosintesis/Convex + CajaInventario | BE6: Caja (snapshot) registra comprador 'M.Gomez' vs asesor actual 'M.Gómez' — revisar si son ventas distintas o la copia está desactualizada. · costo estimado = precio/2.6 (costo original igualaba al precio)
A7: 6 | B7: 31-oct-2025 | C7: Jardín Escondido | D7: 1.23 | E7: Verde Natural | F7: COMERCIAL SUPERIOR | G7: 1 | H7: Cuadrada | K7: Gema | L7: 170385 | O7: ASESOR | P7: M.Echeverry | Q7: VENDIDA | R7: https://tierramadre.app/p/6 | S7: #4000 | T7: Legalizada | AR7: =IFERROR(VLOOKUP($X7,Lotes!$A:$E,5,FALSE())*$U7,"") | AS7: =IF($L7="","",$L7*2.6) -> 443001 | AU7: 443000 | AV7: 443000 | AW7: 0 | AX7: M.Echeverry | AY7: VENDIDO | BA7: https://tierramadre.app/product/6 | BB7: https://drive.google.com/drive/folders/128cd636PXCN_OJNu7Ml-HWO60E0y3nh1 | BC7: 2026-07-18-jardin-escondido-item-6 | BD7: Legacy + Fotosintesis/Convex + CajaInventario | BE7: costo estimado = precio/2.6 (costo original igualaba al precio)
A8: 7 | B8: 31-oct-2025 | C8: Trilogía | D8: 1.43 | E8: Verde Natural | F8: COMERCIAL SUPERIOR | G8: 3 | H8: Cuadrada | K8: Gema | L8: 218077 | O8: ASESOR | P8: M.Gómez | Q8: VENDIDA | R8: https://tierramadre.app/p/7 | S8: #4000 | T8: Legalizada | AR8: =IFERROR(VLOOKUP($X8,Lotes!$A:$E,5,FALSE())*$U8,"") | AS8: =IF($L8="","",$L8*2.6) -> 567000.2 | AU8: 567000 | AV8: 567000 | AW8: 0 | AX8: M.Gomez | AY8: VENDIDO | BA8: https://tierramadre.app/product/7 | BB8: https://drive.google.com/drive/folders/1C6LBBdS68h22LsCBhGH9likIuIt0ioOJ | BC8: 2026-07-18-trilogia-item-7 | BD8: Legacy + Fotosintesis/Convex + CajaInventario | BE8: Caja (snapshot) registra comprador 'M.Gomez' vs asesor actual 'M.Gómez' — revisar si son ventas distintas o la copia está desactualizada. · costo estimado = precio/2.6 (costo original igualaba al precio)
A9: 8 | B9: 31-oct-2025 | C9: Bambú | D9: 0.83 | E9: Verde Natural | F9: COMERCIAL SUPERIOR | G9: 1 | H9: Cuadrada | K9: Gema | L9: 115000 | O9: ASESOR | P9: M.Campuzano | Q9: VENDIDA | R9: https://tierramadre.app/p/8 | S9: #4000 | T9: Legalizada | AR9: =IFERROR(VLOOKUP($X9,Lotes!$A:$E,5,FALSE())*$U9,"") | AS9: =IF($L9="","",$L9*2.6) -> 299000 | AU9: 299000 | AV9: 299000 | AW9: 0 | AX9: M.Campuzano | AY9: VENDIDO | BA9: https://tierramadre.app/product/8 | BB9: https://drive.google.com/drive/folders/1_MmIVPvsjdJvwFiJHj9b8hux-UU4HrB8 | BC9: 2026-07-18-bambu-item-8 | BD9: Legacy + Fotosintesis/Convex + CajaInventario | BE9: costo estimado = precio/2.6 (costo original igualaba al precio)
A10: 9 | B10: 31-oct-2025 | C10: Turquesa | D10: 0.66 | E10: Verde Natural | F10: COMERCIAL ESTÁNDAR | G10: 1 | H10: Esmeralda | K10: Gema | L10: 91538 | O10: EMBAJADOR | P10: Isa la Negra Vikinga Warrior Portocarrero | Q10: VENDIDA | R10: https://tierramadre.app/p/9 | S10: #4000 | T10: Legalizada | AR10: =IFERROR(VLOOKUP($X10,Lotes!$A:$E,5,FALSE())*$U10,"") | AS10: =IF($L10="","",$L10*2.6) -> 237998.8 | AU10: 238000 | AV10: 238000 | AW10: 0 | AX10: Isa la Negra Vikinga Warrior Portocarrero | AY10: VENDIDO | BA10: https://tierramadre.app/product/9 | BB10: https://drive.google.com/drive/folders/1i7hpPgZYv3ypngGeSLG2vZZOOcMOKocb | BC10: 2026-07-18-turquesa-item-9 | BD10: Legacy + Fotosintesis/Convex + CajaInventario | BE10: costo estimado = precio/2.6 (costo original igualaba al precio)
A11: 10 | B11: 31-oct-2025 | C11: Jazmin | D11: 0.99 | E11: Verde Natural | F11: COMERCIAL ESTÁNDAR | G11: 1 | H11: Esmeralda | K11: Gema | L11: 89500 | O11: OFI.CALI | P11: M.Campuzano | Q11: DISPONIBLE | R11: https://tierramadre.app/p/10 | S11: #4000 | X11: C-058 | AF11: Gola | AR11: =IFERROR(VLOOKUP($X11,Lotes!$A:$E,5,FALSE())*$U11,"") -> 0 | AS11: =IF($L11="","",$L11*2.6) -> 232700 | AU11: 358000 | AV11: 358000 | AW11: 358000 | AX11: Tierra Madre | AY11: Disponible | BA11: https://tierramadre.app/product/10 | BB11: https://drive.google.com/drive/folders/1UDgx_-NJ4dzukfdAEZ6Docmqb9mafGxS | BC11: 2026-07-13-jazmin-item-10 · 2026-07-17-jazmin-item-10-vendida | BD11: Legacy + Fotosintesis/Convex + ModeloPrecios + CajaInventario | BE11: Calidad difiere: legacy=Comercial Estándar vs modeloPrecios=C. Estándar | Caja (snapshot) registra comprador 'Tierra Madre' vs asesor actual 'M.Campuzano' — revisar si son ventas distintas o la copia está desactualizada.
A12: 11 | B12: 31-oct-2025 | C12: Rosario | D12: 0.81 | E12: Verde Natural | F12: COMERCIAL ESTÁNDAR | G12: 1 | H12: Redonda | K12: Gema | L12: 113077 | O12: ASESOR | P12: A.Molano | Q12: VENDIDA | R12: https://tierramadre.app/p/11 | S12: #4000 | T12: Legalizada | AR12: =IFERROR(VLOOKUP($X12,Lotes!$A:$E,5,FALSE())*$U12,"") | AS12: =IF($L12="","",$L12*2.6) -> 294000.2 | AU12: 294000 | AV12: 264600 | AW12: 0 | AX12: A.Molano | AY12: VENDIDO | BA12: https://tierramadre.app/product/11 | BB12: https://drive.google.com/drive/folders/1Ae8JfDOC4WH7JWR9YzCnCEceMnuYPlDZ | BC12: 2026-07-18-rosario-item-11 | BD12: Legacy + Fotosintesis/Convex + CajaInventario | BE12: costo estimado = precio/2.6 (costo original igualaba al precio)
A13: 12 | B13: 31-oct-2025 | C13: Baby Green | D13: 0.46 | E13: Verde Limón | F13: COMERCIAL SUPERIOR | G13: 1 | H13: Redonda | K13: Gema | L13: 65385 | O13: ASESOR | P13: A.Molano | Q13: VENDIDA | R13: https://tierramadre.app/p/12 | S13: #4000 | T13: Legalizada | AR13: =IFERROR(VLOOKUP($X13,Lotes!$A:$E,5,FALSE())*$U13,"") | AS13: =IF($L13="","",$L13*2.6) -> 170001 | AU13: 170000 | AV13: 125800 | AW13: 0 | AX13: A.Molano | AY13: VENDIDO | BA13: https://tierramadre.app/product/12 | BB13: https://drive.google.com/drive/folders/11lpxWncpyBq_YoAs22kOIOrz_greUMmn | BC13: 2026-07-18-baby-green-item-12 | BD13: Legacy + Fotosintesis/Convex + CajaInventario | BE13: costo estimado = precio/2.6 (costo original igualaba al precio)
A14: 13 | B14: 31-oct-2025 | C14: Amazonas | D14: 0.41 | E14: Verde Limón | F14: COMERCIAL FINA | G14: 1 | H14: Ovalo | K14: Gema | L14: 63846 | O14: EMBAJADOR | P14: Isa la Negra Vikinga Warrior Portocarrero | Q14: VENDIDA | R14: https://tierramadre.app/p/13 | S14: #4000 | T14: Legalizada | AR14: =IFERROR(VLOOKUP($X14,Lotes!$A:$E,5,FALSE())*$U14,"") | AS14: =IF($L14="","",$L14*2.6) -> 165999.6 | AU14: 166000 | AV14: 166000 | AW14: 0 | AX14: Isa la Negra Vikinga Warrior Portocarrero | AY14: VENDIDO | BA14: https://tierramadre.app/product/13 | BB14: https://drive.google.com/drive/folders/129kesHdlmj7_0yUitRhzsYGinKqx_RdZ | BC14: 2026-07-18-amazonas-item-13 | BD14: Legacy + Fotosintesis/Convex + CajaInventario | BE14: costo estimado = precio/2.6 (costo original igualaba al precio)
A15: 14 | B15: 31-oct-2025 | C15: Leticia | D15: 0.33 | E15: Verde Limón | F15: COMERCIAL FINA | G15: 1 | H15: Redonda | K15: Gema | L15: 51538 | O15: ASESOR | P15: M.Campuzano | Q15: VENDIDA | R15: https://tierramadre.app/p/14 | S15: #4000 | T15: Legalizada | AR15: =IFERROR(VLOOKUP($X15,Lotes!$A:$E,5,FALSE())*$U15,"") | AS15: =IF($L15="","",$L15*2.6) -> 133998.8 | AU15: 134000 | AV15: 134000 | AW15: 0 | AX15: Tierra Madre | AY15: VENDIDO | BA15: https://tierramadre.app/product/14 | BB15: https://drive.google.com/drive/folders/1ZMZ6uPiT2bgQl9Y1GfKgM7QWJUnfczX_ | BC15: 2026-07-18-leticia-item-14 | BD15: Legacy + Fotosintesis/Convex + CajaInventario | BE15: Caja (snapshot) registra comprador 'Tierra Madre' vs asesor actual 'M.Campuzano' — revisar si son ventas distintas o la copia está desactualizada. · costo estimado = precio/2.6 (costo original igualaba al precio)
A16: 15 | B16: 31-oct-2025 | C16: Madre Selva | D16: 0.75 | E16: Verde Limón | F16: COMERCIAL FINA | G16: 1 | H16: Cuadrada | K16: Gema | L16: 116538 | O16: ASESOR | P16: A.Molano | Q16: VENDIDA | R16: https://tierramadre.app/p/15 | S16: #4000 | T16: Legalizada | AR16: =IFERROR(VLOOKUP($X16,Lotes!$A:$E,5,FALSE())*$U16,"") | AS16: =IF($L16="","",$L16*2.6) -> 302998.8 | AU16: 303000 | AV16: 224220 | AW16: 0 | AX16: A.Molano | AY16: VENDIDO | BA16: https://tierramadre.app/product/15 | BB16: https://drive.google.com/drive/folders/1O-7j5NRL1CdfqmIr7fAG6HGO3VJPK3mt | BC16: 2026-07-18-madre-selva-item-15 | BD16: Legacy + Fotosintesis/Convex + CajaInventario | BE16: costo estimado = precio/2.6 (costo original igualaba al precio)
A17: 16 | B17: 31-oct-2025 | C17: Pacífico | D17: 0.55 | E17: Verde Limón | F17: COMERCIAL FINA | G17: 1 | H17: Cuadrada | K17: Gema | L17: 85385 | O17: ASESOR | P17: A.Molano | Q17: VENDIDA | R17: https://tierramadre.app/p/16 | S17: #4000 | T17: Legalizada | AR17: =IFERROR(VLOOKUP($X17,Lotes!$A:$E,5,FALSE())*$U17,"") | AS17: =IF($L17="","",$L17*2.6) -> 222001 | AU17: 222000 | AV17: 164280 | AW17: 0 | AX17: A.Molano | AY17: VENDIDO | BA17: https://tierramadre.app/product/16 | BB17: https://drive.google.com/drive/folders/1nFmRjpaKiJegs_yj-ZhoOsY8VvUK4Mr0 | BC17: 2026-07-18-pacifico-item-16 | BD17: Legacy + Fotosintesis/Convex + CajaInventario | BE17: costo estimado = precio/2.6 (costo original igualaba al precio)
A18: 17 | B18: 31-oct-2025 | C18: Mística | D18: 0.38 | E18: Verde Limón | F18: COMERCIAL SUPERIOR | G18: 1 | H18: Lágrima | K18: Gema | L18: 154000 | O18: ASESOR | P18: M.Gómez | Q18: VENDIDA | R18: https://tierramadre.app/p/17 | S18: #4000 | T18: Legalizada | AR18: =IFERROR(VLOOKUP($X18,Lotes!$A:$E,5,FALSE())*$U18,"") | AS18: =IF($L18="","",$L18*2.6) -> 400400 | AU18: 231000 | AV18: 147840 | AW18: 0 | AX18: M.Gomez | AY18: VENDIDO | BA18: https://tierramadre.app/product/17 | BB18: https://drive.google.com/drive/folders/1AGZwNq6hnFV6zFgJVZWSkVDOC4c5Kq4J | BC18: 2026-07-18-mistica-item-17 | BD18: Legacy + Fotosintesis/Convex + CajaInventario | BE18: Caja (snapshot) registra comprador 'M.Gomez' vs asesor actual 'M.Gómez' — revisar si son ventas distintas o la copia está desactualizada.
A19: 18 | B19: 31-oct-2025 | C19: Pachitas | D19: 0.74 | E19: Verde Limón | F19: COMERCIAL FINA | G19: 2 | H19: Cuadrada | K19: Gema | L19: 299000 | O19: ASESOR | P19: M.Gómez | Q19: VENDIDA | R19: https://tierramadre.app/p/18 | S19: #4000 | T19: Pte Legalizar | AR19: =IFERROR(VLOOKUP($X19,Lotes!$A:$E,5,FALSE())*$U19,"") | AS19: =IF($L19="","",$L19*2.6) -> 777400 | AU19: 448500 | AV19: 448500 | AW19: 296500 | AX19: M.Gomez | AY19: CARTERA | BA19: https://tierramadre.app/product/18 | BB19: https://drive.google.com/drive/folders/1V9EK9N6WjIzsImGztuqojvoYtpohLTrS | BC19: 2026-07-18-pachitas-item-18 | BD19: Legacy + Fotosintesis/Convex + CajaInventario | BE19: Caja (snapshot) registra comprador 'M.Gomez' vs asesor actual 'M.Gómez' — revisar si son ventas distintas o la copia está desactualizada.
A20: 19 | B20: 31-oct-2025 | C20: 5 Estrellas | D20: 2.14 | E20: Verde Limón | F20: COMERCIAL FINA | G20: 5 | H20: Cuadrada | K20: Gema | L20: 304231 | O20: ASESOR | P20: M.Gómez | Q20: VENDIDA | R20: https://tierramadre.app/p/19 | S20: #4000 | T20: Legalizada | AR20: =IFERROR(VLOOKUP($X20,Lotes!$A:$E,5,FALSE())*$U20,"") | AS20: =IF($L20="","",$L20*2.6) -> 791000.6 | AU20: 791000 | AV20: 780796.1 | AW20: 796.1 | AX20: M.Gomez | AY20: VENDIDO | BA20: https://tierramadre.app/product/19 | BB20: https://drive.google.com/drive/folders/1hWzLBarjP25vCmvxEnDtbm22Cln7Sgq8 | BC20: 2026-07-18-5-estrellas-item-19 | BD20: Legacy + Fotosintesis/Convex + CajaInventario | BE20: Caja (snapshot) registra comprador 'M.Gomez' vs asesor actual 'M.Gómez' — revisar si son ventas distintas o la copia está desactualizada. · costo estimado = precio/2.6 (costo original igualaba al precio)
A21: 20 | B21: 31-oct-2025 | C21: 2 Pinticas | D21: 0.73 | E21: Verde Limón | F21: COMERCIAL FINA | G21: 2 | H21: Esmeralda | K21: Gema | L21: 270000 | O21: ASESOR | P21: Paola Daza | Q21: VENDIDA | R21: https://tierramadre.app/p/20 | S21: #4000 | T21: Legalizada | AR21: =IFERROR(VLOOKUP($X21,Lotes!$A:$E,5,FALSE())*$U21,"") | AS21: =IF($L21="","",$L21*2.6) -> 702000 | AU21: 405000 | AV21: 392850 | AW21: 0 | AX21: Paola Daza | AY21: VENDIDO | BA21: https://tierramadre.app/product/20 | BB21: https://drive.google.com/drive/folders/1uEbSr_4XGRexukQBE3gtST6NCViBi_r8 | BC21: 2026-07-18-2-pinticas-item-20 | BD21: Legacy + Fotosintesis/Convex + CajaInventario
A22: 21 | B22: 31-oct-2025 | C22: Dualidad | D22: 1.63 | E22: Verde Limón | F22: COMERCIAL ESTÁNDAR | G22: 2 | H22: Cuadrada | K22: Gema | L22: 210769 | O22: ASESOR | P22: A.Molano | Q22: VENDIDA | R22: https://tierramadre.app/p/21 | S22: #4000 | T22: Legalizada | AR22: =IFERROR(VLOOKUP($X22,Lotes!$A:$E,5,FALSE())*$U22,"") | AS22: =IF($L22="","",$L22*2.6) -> 547999.4 | AU22: 548000 | AV22: 411000 | AW22: 0 | AX22: A.Molano | AY22: VENDIDO | BA22: https://tierramadre.app/product/21 | BB22: https://drive.google.com/drive/folders/1fpGsWEih1WDqEYbVpKLXnScNMxdu_BoP | BC22: 2026-07-18-dualidad-item-21 | BD22: Legacy + Fotosintesis/Convex + CajaInventario | BE22: costo estimado = precio/2.6 (costo original igualaba al precio)
A23: 22 | B23: 31-oct-2025 | C23: Brasil | D23: 1.14 | E23: Verde Limón | F23: COMERCIAL ESTÁNDAR | G23: 1 | H23: Redonda | K23: Gema | L23: 147308 | O23: ASESOR | P23: A.Molano | Q23: VENDIDA | R23: https://tierramadre.app/p/22 | S23: #4000 | T23: Legalizada | AR23: =IFERROR(VLOOKUP($X23,Lotes!$A:$E,5,FALSE())*$U23,"") | AS23: =IF($L23="","",$L23*2.6) -> 383000.8 | AU23: 383000 | AV23: 283420 | AW23: 0 | AX23: A.Molano | AY23: VENDIDO | BA23: https://tierramadre.app/product/22 | BB23: https://drive.google.com/drive/folders/1UsrsRKJQIUF-T2t4LyeFMhMXut5WUgMv | BC23: 2026-07-18-brasil-item-22 | BD23: Legacy + Fotosintesis/Convex + CajaInventario | BE23: costo estimado = precio/2.6 (costo original igualaba al precio)
A24: 23 | B24: 31-oct-2025 | C24: Guajira | D24: 0.58 | E24: Verde Limón | F24: COMERCIAL ESTÁNDAR | G24: 1 | H24: Redonda | K24: Gema | L24: 195000 | O24: ASESOR | P24: Pablito | Q24: VENDIDA | R24: https://tierramadre.app/p/23 | S24: #4000 | T24: Legalizada | AR24: =IFERROR(VLOOKUP($X24,Lotes!$A:$E,5,FALSE())*$U24,"") | AS24: =IF($L24="","",$L24*2.6) -> 507000 | AU24: 234000 | AV24: 200070 | AW24: 70 | AX24: Pablito | AY24: VENDIDO | BA24: https://tierramadre.app/product/23 | BB24: https://drive.google.com/drive/folders/1NqWuRiC1oc5C-vziwQR5flgv5n2pbAwb | BC24: 2026-07-18-guajira-item-23 | BD24: Legacy + Fotosintesis/Convex + CajaInventario
A25: 24 | B25: 31-oct-2025 | C25: Aqua | D25: 0.44 | E25: Verde Limón | F25: COMERCIAL ESTÁNDAR | G25: 1 | H25: Lágrima | K25: Gema | L25: 56923 | O25: ASESOR | P25: M.Campuzano | Q25: VENDIDA | R25: https://tierramadre.app/p/24 | S25: #4000 | T25: Legalizada | AR25: =IFERROR(VLOOKUP($X25,Lotes!$A:$E,5,FALSE())*$U25,"") | AS25: =IF($L25="","",$L25*2.6) -> 147999.8 | AU25: 148000 | AV25: 148000 | AW25: 0 | AX25: Tierra Madre | AY25: VENDIDO | BA25: https://tierramadre.app/product/24 | BB25: https://drive.google.com/drive/folders/1M688e1omkth5-S86LbXHSgIUd0jCvXD_ | BC25: 2026-07-18-aqua-item-24 | BD25: Legacy + Fotosintesis/Convex + CajaInventario | BE25: Caja (snapshot) registra comprador 'Tierra Madre' vs asesor actual 'M.Campuzano' — revisar si son ventas distintas o la copia está desactualizada. · costo estimado = precio/2.6 (costo original igualaba al precio)
A26: 25 | B26: 31-oct-2025 | C26: Las Emperatrices | D26: 0.41 | E26: Verde Menta | F26: COMERCIAL FINA | G26: 2 | H26: Cuadrada | K26: Gema | L26: 63846 | O26: ASESOR | P26: A.Molano | Q26: VENDIDA | R26: https://tierramadre.app/p/25 | S26: #4000 | T26: Legalizada | AR26: =IFERROR(VLOOKUP($X26,Lotes!$A:$E,5,FALSE())*$U26,"") | AS26: =IF($L26="","",$L26*2.6) -> 165999.6 | AU26: 166000 | AV26: 122840 | AW26: 0 | AX26: A.Molano | AY26: VENDIDO | BA26: https://tierramadre.app/product/25 | BB26: https://drive.google.com/drive/folders/11JzkwLX7sllytq36gOy557XUrIcuEOpS | BC26: 2026-07-18-las-emperatrices-item-25 | BD26: Legacy + Fotosintesis/Convex + CajaInventario | BE26: costo estimado = precio/2.6 (costo original igualaba al precio)
A27: 26 | B27: 31-oct-2025 | C27: Madre e Hija | D27: 0.21 | E27: Verde Menta | F27: COMERCIAL FINA | G27: 2 | H27: Esmeralda | K27: Gema | L27: 32692 | O27: EMBAJADOR | P27: Isa la Negra Vikinga Warrior Portocarrero | Q27: VENDIDA | R27: https://tierramadre.app/p/26 | S27: #4000 | T27: Legalizada | AR27: =IFERROR(VLOOKUP($X27,Lotes!$A:$E,5,FALSE())*$U27,"") | AS27: =IF($L27="","",$L27*2.6) -> 84999.2 | AU27: 85000 | AV27: 85000 | AW27: 0 | AX27: Isa la Negra Vikinga Warrior Portocarrero | AY27: VENDIDO | BA27: https://tierramadre.app/product/26 | BB27: https://drive.google.com/drive/folders/1LXXT8Kc55Rle2B4YP7DMm9Bd0W77-I5c | BC27: 2026-07-18-madre-e-hija-item-26 | BD27: Legacy + Fotosintesis/Convex + CajaInventario | BE27: costo estimado = precio/2.6 (costo original igualaba al precio)
A28: 27 | B28: 31-oct-2025 | C28: Hijos de la Tierra | D28: 0.13 | E28: Verde Menta | F28: COMERCIAL FINA | G28: 8 | H28: Redonda | K28: Gema | L28: 160769 | O28: ASESOR | P28: M.Gómez | Q28: VENDIDA | R28: https://tierramadre.app/p/27 | S28: #4000 | T28: Legalizada | AR28: =IFERROR(VLOOKUP($X28,Lotes!$A:$E,5,FALSE())*$U28,"") | AS28: =IF($L28="","",$L28*2.6) -> 417999.4 | AU28: 418000 | AV28: 249128 | AW28: 0 | AX28: M.Gomez | AY28: VENDIDO | BA28: https://tierramadre.app/product/27 | BB28: https://drive.google.com/drive/folders/1Notlg6O4K2JcJ1OJtwicXEmGyk9nGmub | BC28: 2026-07-18-hijos-de-la-tierra-item-27 | BD28: Legacy + Fotosintesis/Convex + CajaInventario | BE28: Caja (snapshot) registra comprador 'M.Gomez' vs asesor actual 'M.Gómez' — revisar si son ventas distintas o la copia está desactualizada. · costo estimado = precio/2.6 (costo original igualaba al precio)
A29: 28 | B29: 31-oct-2025 | C29: Las 3 Marías | D29: 0.33 | E29: Verde Menta | F29: COMERCIAL FINA | G29: 3 | H29: Redonda | K29: Gema | L29: 51538 | O29: ASESOR | P29: Jennifer.Florez | Q29: VENDIDA | R29: https://tierramadre.app/p/28 | S29: #4000 | T29: Legalizada | AR29: =IFERROR(VLOOKUP($X29,Lotes!$A:$E,5,FALSE())*$U29,"") | AS29: =IF($L29="","",$L29*2.6) -> 133998.8 | AU29: 134000 | AV29: 85760 | AW29: 0 | AX29: Jenifer.Florez | AY29: VENDIDO | BA29: https://tierramadre.app/product/28 | BB29: https://drive.google.com/drive/folders/1T5Co05DVsSoOcuCglRd9RUB_EIVGwnSl | BC29: 2026-07-18-las-3-marias-item-28 | BD29: Legacy + Fotosintesis/Convex + CajaInventario | BE29: Caja (snapshot) registra comprador 'Jenifer.Florez' vs asesor actual 'Jennifer.Florez' — revisar si son ventas distintas o la copia está desactualizada. · costo estimado = precio/2.6 (costo original igualaba al precio)
A30: 29 | B30: 11-nov-2025 | C30: Hijos del sol | D30: 1.73 | E30: Verde Limón | F30: COMERCIAL SÚPER FINA | G30: 2 | H30: Esmeralda | I30: Largo x Ancho | J30: 6.2 × 5.4 mm | K30: Gema | L30: 293077 | O30: ASESOR | P30: M.Campuzano | Q30: VENDIDA | R30: https://tierramadre.app/p/29 | S30: 11:11 | T30: Pte Fecha x Legalizar | AR30: =IFERROR(VLOOKUP($X30,Lotes!$A:$E,5,FALSE())*$U30,"") | AS30: =IF($L30="","",$L30*2.6) -> 762000.2 | AU30: 762000 | AV30: 762000 | AW30: 762000 | AX30: M.Campuzano | AY30: CARTERA | BA30: https://tierramadre.app/product/29 | BB30: https://drive.google.com/drive/folders/1nU2FfG06DAMolYiu8U5EMZ6UEA-I9gOl | BC30: 2026-07-15-hijos-del-sol-item-29 | BD30: Legacy + Fotosintesis/Convex + CajaInventario | BE30: costo estimado = precio/2.6 (costo original igualaba al precio)
A31: 30 | B31: 11-nov-2025 | C31: Amor Eterno | D31: 1.08 | E31: Verde Limón | F31: COMERCIAL SÚPER FINA | G31: 2 | H31: Esmeralda | I31: Largo x Ancho | J31: 6.2 × 4.3 mm | K31: Gema | L31: 240385 | O31: ASESOR | P31: Jennifer.Florez | Q31: VENDIDA | R31: https://tierramadre.app/p/30 | S31: 11:11 | T31: Legalizada | AR31: =IFERROR(VLOOKUP($X31,Lotes!$A:$E,5,FALSE())*$U31,"") | AS31: =IF($L31="","",$L31*2.6) -> 625001 | AU31: 625000 | AV31: 400000 | AW31: 0 | AX31: Jenifer.Florez | AY31: VENDIDO | BA31: https://tierramadre.app/product/30 | BB31: https://drive.google.com/drive/folders/1szKVIxqzH4rULLps4t7uEK87fvZrQPAz | BC31: 2026-07-18-amor-eterno-item-30 | BD31: Legacy + Fotosintesis/Convex + CajaInventario | BE31: peso ct recuperado de serial Excel · Caja (snapshot) registra comprador 'Jenifer.Florez' vs asesor actual 'Jennifer.Florez' — revisar si son ventas distintas o la copia está desactualizada. · costo estimado = precio/2.6 (costo original igualaba al precio)
A32: 31 | B32: 11-nov-2025 | C32: Alma Verde | D32: 0.48 | E32: Verde Limón | F32: COMERCIAL SÚPER FINA | G32: 1 | H32: Cuadrada | I32: Largo x Ancho | J32: 5.1 × 4.4 mm | K32: Gema | L32: 85385 | O32: ASESOR | P32: A.Molano | Q32: VENDIDA | R32: https://tierramadre.app/p/31 | S32: 11:11 | T32: Legalizada | AR32: =IFERROR(VLOOKUP($X32,Lotes!$A:$E,5,FALSE())*$U32,"") | AS32: =IF($L32="","",$L32*2.6) -> 222001 | AU32: 222000 | AV32: 164280 | AW32: 0 | AX32: A.Molano | AY32: VENDIDO | BA32: https://tierramadre.app/product/31 | BB32: https://drive.google.com/drive/folders/1iXzJMscyh24O_lq5xgd1n549HpKfwzwJ | BC32: 2026-07-18-alma-verde-item-31 | BD32: Legacy + Fotosintesis/Convex + CajaInventario | BE32: costo estimado = precio/2.6 (costo original igualaba al precio)
A33: 32 | B33: 11-nov-2025 | C33: Venus | D33: 0.43 | E33: Verde Limón | F33: COMERCIAL SÚPER FINA | G33: 1 | H33: Esmeralda | I33: Largo x Ancho | J33: 4 × 5 mm | K33: Gema | L33: 76538 | O33: ASESOR | P33: A.Molano | Q33: VENDIDA | R33: https://tierramadre.app/p/32 | S33: 11:11 | T33: Legalizada | AR33: =IFERROR(VLOOKUP($X33,Lotes!$A:$E,5,FALSE())*$U33,"") | AS33: =IF($L33="","",$L33*2.6) -> 198998.8 | AU33: 199000 | AV33: 35820 | AW33: -223 | AX33: A.Molano | AY33: VENDIDO | BA33: https://tierramadre.app/product/32 | BB33: https://drive.google.com/drive/folders/1K516L8m71wHAMHjSgsk-uhVPFaMYJ-bK | BC33: 2026-07-18-venus-item-32 | BD33: Legacy + Fotosintesis/Convex + CajaInventario | BE33: costo estimado = precio/2.6 (costo original igualaba al precio)
A34: 33 | B34: 11-nov-2025 | C34: Diosa de la Laguna | D34: 0.45 | E34: Verde Limón | F34: COMERCIAL SÚPER FINA | G34: 1 | H34: Ovalo | I34: Largo x Ancho | J34: 4 × 5 mm | K34: Gema | L34: 111923 | O34: ASESOR | P34: A.Molano | Q34: VENDIDA | R34: https://tierramadre.app/p/33 | S34: 11:11 | T34: Legalizada | AR34: =IFERROR(VLOOKUP($X34,Lotes!$A:$E,5,FALSE())*$U34,"") | AS34: =IF($L34="","",$L34*2.6) -> 290999.8 | AU34: 291000 | AV34: 215340 | AW34: 0 | AX34: A.Molano | AY34: VENDIDO | BA34: https://tierramadre.app/product/33 | BB34: https://drive.google.com/drive/folders/12tstqF-Q4zLQJPs97OM224JhiM19pOi3 | BC34: 2026-07-18-diosa-de-la-laguna-item-33 | BD34: Legacy + Fotosintesis/Convex + CajaInventario | BE34: costo estimado = precio/2.6 (costo original igualaba al precio)
A35: 34 | B35: 11-nov-2025 | C35: Gaia | D35: 0.55 | E35: Verde Limón | F35: COMERCIAL SÚPER FINA | G35: 1 | H35: Redonda | I35: Diámetro | J35: 52 mm | K35: Gema | L35: 105385 | O35: ASESOR | P35: J.I.Florez | Q35: VENDIDA | R35: https://tierramadre.app/p/34 | S35: 11:11 | T35: Legalizada | AR35: =IFERROR(VLOOKUP($X35,Lotes!$A:$E,5,FALSE())*$U35,"") | AS35: =IF($L35="","",$L35*2.6) -> 274001 | AU35: 274000 | AV35: 175360 | AW35: 0 | AX35: J.I.Florez | AY35: VENDIDO | BA35: https://tierramadre.app/product/34 | BB35: https://drive.google.com/drive/folders/1TCCqfotVP1NaI_WQGfgWMV0_2D6bswku | BC35: 2026-07-18-gaia-item-34 | BD35: Legacy + Fotosintesis/Convex + CajaInventario | BE35: costo estimado = precio/2.6 (costo original igualaba al precio)
A36: 35 | B36: 11-nov-2025 | C36: Inspiración Divina | D36: 0.47 | E36: Verde Limón | F36: FINA ESENCIAL | G36: 1 | H36: Ovalo | I36: Largo x Ancho | J36: 4.9 × 4.1 mm | K36: Gema | L36: 117000 | O36: ASESOR | P36: A.Molano | Q36: VENDIDA | R36: https://tierramadre.app/p/35 | S36: 11:11 | T36: Legalizada | AR36: =IFERROR(VLOOKUP($X36,Lotes!$A:$E,5,FALSE())*$U36,"") | AS36: =IF($L36="","",$L36*2.6) -> 304200 | AU36: 304200 | AV36: 225108 | AW36: 0 | AX36: A.Molano | AY36: VENDIDO | BA36: https://tierramadre.app/product/35 | BB36: https://drive.google.com/drive/folders/1swjdgJD9GqwqhzMnhwg8FiClvZHFQ_EY | BC36: 2026-07-18-inspiracion-divina-item-35 | BD36: Legacy + Fotosintesis/Convex + CajaInventario | BE36: costo estimado = precio/2.6 (costo original igualaba al precio)
A37: 36 | B37: 11-nov-2025 | C37: Lunera | D37: 0.46 | E37: Verde Limón | F37: COMERCIAL SUPERIOR | G37: 1 | H37: Ovalo | I37: Largo x Ancho | J37: 5.0 × 4.3 mm | K37: Gema | L37: 78846 | O37: ASESOR | P37: A.Molano | Q37: VENDIDA | R37: https://tierramadre.app/p/36 | S37: 11:11 | T37: Legalizada | AR37: =IFERROR(VLOOKUP($X37,Lotes!$A:$E,5,FALSE())*$U37,"") | AS37: =IF($L37="","",$L37*2.6) -> 204999.6 | AU37: 205000 | AV37: 151700 | AW37: 0 | AX37: A.Molano | AY37: VENDIDO | BA37: https://tierramadre.app/product/36 | BB37: https://drive.google.com/drive/folders/1UAx_59A5wbey4ALZxhcbj28uU_Lg54xL | BC37: 2026-07-18-lunera-item-36 | BD37: Legacy + Fotosintesis/Convex + CajaInventario | BE37: costo estimado = precio/2.6 (costo original igualaba al precio)
A38: 37 | B38: 11-nov-2025 | C38: Ojo de Zeus | D38: 0.35 | E38: Verde Limón | F38: COMERCIAL FINA | G38: 1 | H38: Redonda | I38: Diámetro | J38: 4.8 mm | K38: Gema | L38: 64615 | O38: EMBAJADOR | P38: Isa la Negra Vikinga Warrior Portocarrero | Q38: VENDIDA | R38: https://tierramadre.app/p/37 | S38: 11:11 | T38: Pte Fecha x Legalizar | AR38: =IFERROR(VLOOKUP($X38,Lotes!$A:$E,5,FALSE())*$U38,"") | AS38: =IF($L38="","",$L38*2.6) -> 167999 | AU38: 168000 | AV38: 168000 | AW38: 168000 | AX38: Isa la Negra Vikinga Warrior Portocarrero | AY38: CARTERA | BA38: https://tierramadre.app/product/37 | BB38: https://drive.google.com/drive/folders/1JegA-Khcl-NBd-I-N8YyvhvColhdXvaa | BC38: 2026-07-18-ojo-de-zeus-item-37 | BD38: Legacy + Fotosintesis/Convex + CajaInventario | BE38: costo estimado = precio/2.6 (costo original igualaba al precio)
A39: 38 | B39: 11-nov-2025 | C39: Infinito | D39: 0.5 | E39: Verde Limón | F39: COMERCIAL FINA | G39: 1 | H39: Cuadrada | I39: Largo x Ancho | J39: 4.8 × 4.8 mm | K39: Gema | L39: 240000 | O39: ASESOR | P39: K.Pineda | Q39: VENDIDA | R39: https://tierramadre.app/p/38 | S39: 11:11 | T39: Legalizada | AR39: =IFERROR(VLOOKUP($X39,Lotes!$A:$E,5,FALSE())*$U39,"") | AS39: =IF($L39="","",$L39*2.6) -> 624000 | AU39: 360000 | AV39: 288000 | AW39: 0 | AX39: K.Pineda | AY39: VENDIDO | BA39: https://tierramadre.app/product/38 | BB39: https://drive.google.com/drive/folders/1aGb44P2X_RXl-MO9BbyWsCJ4q9ndQkis | BC39: 2026-07-18-infinito-item-38 | BD39: Legacy + Fotosintesis/Convex + CajaInventario
A40: 39 | B40: 11-nov-2025 | C40: Galaxia | D40: 0.55 | E40: Verde Limón | F40: COMERCIAL SUPERIOR | G40: 1 | H40: Redonda | I40: Largo x Ancho | J40: 55 mm | K40: Gema | L40: 73077 | O40: ASESOR | P40: M.Echeverry | Q40: VENDIDA | R40: https://tierramadre.app/p/39 | S40: 11:11 | AR40: =IFERROR(VLOOKUP($X40,Lotes!$A:$E,5,FALSE())*$U40,"") | AS40: =IF($L40="","",$L40*2.6) -> 190000.2 | AU40: 190000 | AV40: 190000 | AW40: 0 | AX40: M.Echeverry | AY40: VENDIDO | BA40: https://tierramadre.app/product/39 | BB40: https://drive.google.com/drive/folders/1Rd8K4VUjmrTZT0neqkRQKK5umtGSAepa | BC40: 2026-07-18-galaxia-item-39 | BD40: Legacy + Fotosintesis/Convex + CajaInventario | BE40: costo estimado = precio/2.6 (costo original igualaba al precio)
...

Sheet Lotes
A1: loteId | B1: providerNombre | C1: fechaRecepcion | D1: pesoTotalQuilates | E1: costoTotalCOP | F1: unidadesDeclaradas | G1: formaPago | H1: metodoContado | I1: fechaVencimiento | J1: numeroCuotas | K1: numeroFactura | L1: urlFactura | M1: notas | N1: estado | O1: renombreLote | P1: tratamiento | Q1: mina | R1: sede | S1: operadorNombre | T1: operadorRol | U1: mostrarComoLote
A2: B-001·anulado | B2: Edwin Mauricio Ruiz | C2: 2026-05-26 00:00:00 | E2: 150000 | F2: 1 | G2: contado | H2: transferencia | N2: cancelado | R2: B | S2: Kevin Pineda Pérez | T2: captura
A3: C-001 | B3: Edwin Mauricio Ruiz | C3: 2026-05-25 00:00:00 | D3: 37.3 | E3: 4900000 | F3: 190 | G3: contado | H3: transferencia | M3: Perfecto para topitos ,buen tono , buen brillo , 7,3ct calibrados | N3: abierto
A4: C-002 | B4: Edwin Mauricio Ruiz | C4: 2026-05-25 00:00:00 | D4: 9.63 | E4: 1200000 | F4: 2 | G4: credito | H4: transferencia | I4: 2026-08-31 00:00:00 | J4: 1 | K4: N/A | L4: N/A | M4: Exoticas | N4: publicado
A5: C-003 | B5: Edwin Mauricio Ruiz | C5: 2026-05-25 00:00:00 | D5: 71 | E5: 650000 | F5: 5 | G5: contado | H5: transferencia | M5: Comprado 15 mayo del 2026 Morralla de calidad Difícil de conseguir | Reabierto por kpp.coomunity@gmail.com | N5: publicado | O5: Rocas de Venus | P5: Estándar | Q5: Boyacá | R5: C | S5: Maritza Rodriguez | T5: captura
A6: C-004 | B6: Edwin Mauricio Ruiz | C6: 2026-05-25 00:00:00 | D6: 331.1 | E6: 500000 | F6: 7 | G6: contado | H6: transferencia | M6: La mitad del lote (6)/ea para producto propio | N6: publicado | O6: Asteroides Verdes II | P6: Natural | Q6: Boyacá | R6: C | S6: Maritza Rodriguez | T6: captura
A7: C-005 | B7: Edwin Mauricio Ruiz | C7: 2026-05-25 00:00:00 | D7: 300 | E7: 500000 | F7: 2 | G7: contado | H7: transferencia | N7: publicado | O7: Asteroides Verdes III | P7: Natural | Q7: Boyacá | R7: C | S7: Maritza Rodriguez | T7: captura
A8: C-006 | B8: Edwin Mauricio Ruiz | C8: 2026-05-25 00:00:00 | E8: 1300000 | F8: 6 | G8: contado | H8: transferencia | M8: Reserva Talismanes de Brielah | Reabierto por kpp.coomunity@gmail.com | N8: abierto | O8: Jardín Secreto | P8: Estándar | Q8: Boyacá | R8: C | S8: Maritza Rodriguez | T8: captura
A9: C-007 | B9: Edwin Mauricio Ruiz | C9: 2026-05-25 00:00:00 | D9: 40.4 | E9: 1010000 | F9: 6 | G9: contado | H9: transferencia | M9: . | Reabierto por seguimientoproduccion1@gmail.com | N9: publicado | O9: Infinita Felicidad | P9: Pulida | Q9: Boyacá | R9: C | S9: Maritza Rodriguez | T9: captura
A10: C-008 | B10: Edwin Mauricio Ruiz | C10: 2026-05-26 00:00:00 | E10: 5250000 | F10: 4 | G10: contado | H10: transferencia | M10: Para Mercado Internacional | N10: publicado | O10: Trascendencia | P10: Estándar | Q10: Chivor | R10: C | S10: Maritza Rodriguez | T10: captura
A11: C-009 | B11: Edwin Mauricio Ruiz | C11: 2026-05-26 00:00:00 | D11: 1.43 | E11: 3400000 | F11: 1 | G11: credito | I11: 2026-07-30 00:00:00 | J11: 1 | N11: publicado | O11: Orbita Lunar | P11: Estándar | Q11: Muzo | R11: C | S11: Maritza Rodriguez | T11: captura
A12: C-010 | B12: Edwin Mauricio Ruiz | C12: 2026-05-26 00:00:00 | E12: 2010000 | F12: 6 | G12: credito | I12: 2026-06-20 00:00:00 | J12: 1 | M12: Fiadas y con descuento 25% | Reabierto por kvn3toj@gmail.com: Re-dividir C-010: separar 10 gemas nombradas de #351 (Andromeda, Pandora, Namek, Cinturon de Orion) | N12: publicado | O12: Lluvia de Estrellas - L | P12: Estándar | Q12: Chivor | R12: C | S12: Maritza Rodriguez | T12: captura
A13: C-011 | B13: Edwin Mauricio Ruiz | C13: 2026-05-26 00:00:00 | D13: 5.17 | E13: 3100000 | F13: 3 | G13: contado | H13: transferencia | M13: Escazas - Difícil de Conseguir | N13: publicado | O13: Otoño | P13: Estándar | Q13: Boyacá | R13: C | S13: Maritza Rodriguez | T13: captura
A14: C-012 | B14: Edwin Mauricio Ruiz | C14: 2026-05-26 00:00:00 | D14: 37.3 | E14: 4900000 | F14: 8 | G14: contado | H14: transferencia | N14: publicado | O14: Lluvia de Bendiciones | P14: Estándar | Q14: Boyacá | R14: C | S14: Maritza Rodriguez | T14: captura
A15: C-013 | B15: Edwin Mauricio Ruiz | C15: 2026-05-26 00:00:00 | D15: 79 | E15: 500000 | F15: 1 | G15: contado | H15: transferencia | N15: publicado | O15: Rocas Sagradas - G2 | P15: Estándar | Q15: Boyacá | R15: C | S15: Maritza Rodriguez | T15: captura
A16: C-014 | B16: Edwin Mauricio Ruiz | C16: 2026-05-26 00:00:00 | E16: 575000 | F16: 1 | G16: contado | H16: transferencia | M16: montura para topitos | N16: publicado | O16: Montura Topitos Plata Rodinada | P16: Rodinado | R16: C | S16: Maritza Rodriguez | T16: captura
A17: C-015 | B17: Edwin Mauricio Ruiz | C17: 2026-05-26 00:00:00 | D17: 0.86 | E17: 900000 | F17: 9 | G17: credito | I17: 2026-08-31 00:00:00 | J17: 1 | M17: Reabierto por seguimientoproduccion1@gmail.com | N17: cerrado | O17: Libélulas de la Sabana II | P17: Estándar | Q17: Boyacá | R17: C | S17: Maritza Rodriguez | T17: captura
A18: C-016 | B18: Edwin Mauricio Ruiz | C18: 2026-05-26 00:00:00 | E18: 450000 | F18: 1 | G18: credito | I18: 2026-07-31 00:00:00 | J18: 11 | M18: Diseño Especial | N18: publicado | O18: Belleza del Caribe | P18: Natural | Q18: Boyacá | R18: C | S18: Maritza Rodriguez | T18: captura
A19: C-017 | B19: Edwin Mauricio Ruiz | C19: 2026-05-26 00:00:00 | D19: 47.47 | E19: 378000000 | F19: 18 | G19: contado | H19: transferencia | M19: Lote Origen que se movio por todo el mundo | N19: abierto | O19: Origen | P19: Variado | Q19: Chivor | R19: C | S19: Maritza Rodriguez | T19: captura
A20: C-018 | B20: Edwin Mauricio Ruiz | C20: 2026-06-17 00:00:00 | D20: 1.43 | E20: 2717000 | F20: 12 | G20: credito | I20: 2026-07-31 00:00:00 | J20: 1 | M20: Chispitas , estan calibradas para desarrollar productos propios .se abono 1.700.000 contado .saldo Julio 1.017.000 | N20: publicado | O20: Moléculas de Luz | P20: Perma | Q20: Muzo | R20: C | S20: Maritza Rodriguez | T20: captura
A21: C-019 | B21: Edwin Mauricio Ruiz | C21: 2026-06-17 00:00:00 | D21: 0.49 | E21: 600000 | F21: 3 | G21: contado | H21: transferencia | N21: publicado | O21: Partículas de Luz | P21: Perma | Q21: Muzo | R21: C | S21: Maritza Rodriguez | T21: captura
A22: C-020 | B22: Edwin Mauricio Ruiz | C22: 2026-06-17 00:00:00 | D22: 0.22 | E22: 550000 | F22: 1 | G22: contado | H22: transferencia | M22: Reabierto por kpp.coomunity@gmail.com | N22: publicado | O22: Quinto Elemento | P22: Perma | Q22: Muzo | R22: C | S22: Maritza Rodriguez | T22: captura
A23: C-021 | B23: Edwin Mauricio Ruiz | C23: 2026-06-18 00:00:00 | D23: 0.8 | E23: 120000 | F23: 1 | G23: contado | H23: transferencia | M23: Anillo se compro a un proveedor mayorista diferente | N23: publicado | O23: Jupiter | P23: Robinada | Q23: Boyacá | R23: C | S23: Maritza Rodriguez | T23: captura
A24: C-022 | B24: Edwin Mauricio Ruiz | C24: 2026-06-18 00:00:00 | D24: 0.8 | E24: 71400 | F24: 1 | G24: contado | H24: transferencia | M24: Reabierto por kpp.coomunity@gmail.com | N24: publicado | O24: Kiwi | P24: Robinada | Q24: Boyacá | R24: C | S24: Maritza Rodriguez | T24: captura
A25: C-023 | B25: Taller de Bronce El Rey, Joyas Artesanales | C25: 2026-07-08 00:00:00 | E25: 512600 | F25: 3 | G25: contado | H25: transferencia | M25: Línea de producción: Joyería Artesanal · Tipo de esmeralda: Gota y Piedra Cristal | Reabierto por kpp.coomunity@gmail.com | Reabierto por kpp.coomunity@gmail.com | N25: publicado | O25: Renacer de Primavera | R25: C | S25: Kevin Pineda Pérez | T25: captura
A26: C-024 | B26: Taller de Bronce El Rey, Joyas Artesanales | C26: 2026-07-08 00:00:00 | E26: 540000 | F26: 2 | G26: contado | H26: transferencia | N26: publicado | O26: Susurro de Otoño | R26: C | S26: Kevin Pineda Pérez | T26: captura
A27: C-025 | B27: Taller de Bronce El Rey, Joyas Artesanales | C27: 2026-07-08 00:00:00 | E27: 324000 | F27: 2 | G27: contado | H27: transferencia | N27: publicado | O27: Máximo Esplendor | R27: C | S27: Kevin Pineda Pérez | T27: captura
A28: C-026 | B28: Taller de Bronce El Rey, Joyas Artesanales | C28: 2026-07-08 00:00:00 | E28: 70000 | F28: 1 | G28: contado | H28: transferencia | N28: publicado | O28: Infinito Esmeralda | R28: C | S28: Kevin Pineda Pérez | T28: captura
A29: C-027 | B29: Taller de Bronce El Rey, Joyas Artesanales | C29: 2026-07-08 00:00:00 | E29: 270000 | F29: 4 | G29: contado | H29: transferencia | N29: publicado | O29: Pecado orginal | R29: C | S29: Kevin Pineda Pérez | T29: captura
A30: C-028 | B30: Taller de Bronce El Rey, Joyas Artesanales | C30: 2026-07-08 00:00:00 | E30: 340000 | F30: 3 | G30: contado | H30: transferencia | N30: publicado | O30: Naturaleza viva | R30: C | S30: Kevin Pineda Pérez | T30: captura
A31: C-029 | B31: Taller de Bronce El Rey, Joyas Artesanales | C31: 2026-07-08 00:00:00 | E31: 130000 | F31: 2 | G31: contado | H31: transferencia | N31: publicado | O31: kundalini | R31: C | S31: Kevin Pineda Pérez | T31: captura
A32: C-030 | B32: Taller de Bronce El Rey, Joyas Artesanales | C32: 2026-07-08 00:00:00 | E32: 243000 | F32: 3 | G32: contado | H32: transferencia | N32: publicado | O32: Lirios del Agua | R32: C | S32: Kevin Pineda Pérez | T32: captura
A33: C-031 | B33: Taller de Bronce El Rey, Joyas Artesanales | C33: 2026-07-08 00:00:00 | E33: 110000 | F33: 2 | G33: contado | H33: transferencia | N33: publicado | O33: Maestros del aire | R33: C | S33: Kevin Pineda Pérez | T33: captura
A34: C-032 | B34: Taller de Bronce El Rey, Joyas Artesanales | C34: 2026-07-08 00:00:00 | E34: 150000 | F34: 1 | G34: contado | H34: transferencia | N34: publicado | O34: Soberana | R34: C | S34: Kevin Pineda Pérez | T34: captura
A35: C-033 | B35: Taller de Bronce El Rey, Joyas Artesanales | C35: 2026-07-08 00:00:00 | E35: 1230000 | F35: 1 | G35: contado | H35: transferencia | N35: publicado | O35: Noche Eclipsada | R35: C | S35: Kevin Pineda Pérez | T35: captura
A36: C-034 | B36: Edwin Mauricio Ruiz | C36: 2026-07-10 00:00:00 | D36: 142.48 | E36: 585000 | F36: 5 | G36: contado | H36: transferencia | M36: Migración seedBucketC: valores de sub-lote suman $584.950 vs $585.000 declarado (gap $50, rounding en la fuente) — ver reporte. | N36: publicado | O36: Rocas Lunares | R36: C
A37: C-035 | B37: Taller de Bronce El Rey, Joyas Artesanales | C37: 2026-07-10 00:00:00 | E37: 261000 | F37: 1 | G37: contado | H37: transferencia | M37: Migración seedBucketC: lote base en plata, sin ítems individuales aún. | N37: cerrado | O37: Lote base 9 anillos de mujer | R37: C
A38: C-036 | B38: Joyería Legado | C38: 2026-07-10 00:00:00 | E38: 255000 | F38: 1 | G38: contado | H38: transferencia | M38: seedInsumosMarketing: 3 cuentas esféricas verdes ($85.000 c/u). Antes "Balines". Proveedor asumido: Joyería Legado (confirmar). | N38: cerrado | O38: Esferas del Dragón (cuentas verdes) | R38: C
A39: C-037 | B39: Joyería Legado | C39: 2026-07-10 00:00:00 | E39: 24000 | F39: 1 | G39: contado | H39: transferencia | M39: seedInsumosMarketing: 6 cadenas ($4.000 c/u). Proveedor asumido: Joyería Legado (confirmar). | N39: cerrado | O39: Cadenas de baño en oro | R39: C
A40: C-038 | B40: Joyería Legado | C40: 2026-07-10 00:00:00 | E40: 278100 | F40: 1 | G40: contado | H40: transferencia | M40: seedInsumosMarketing: 14 pares: 4mm×6, 3mm×6, 5mm×1, 2mm×1. 1 suelto 3mm usado en Perlita #260. Proveedor asumido: Joyería Legado (confirmar). | N40: cerrado | O40: Topos Redondos (postes aretes) | R40: C
...

Sheet Sublotes
A1: subLoteId | B1: parentLoteId | C1: sede | D1: nombre | E1: itemIds | F1: unidades | G1: totalCostoCOP | H1: estado | I1: mostrarComoLote | J1: notas | K1: createdAt
A2: C-024-G1 | B2: C-024 | C2: C | D2: Susurro de Otoño | E2: 398, 399 | F2: 2 | G2: 540000 | H2: activa | K2: 2026-07-08T09:40:59.890Z
A3: C-025-G1 | B3: C-025 | C3: C | D3: Máximo Esplendor | E3: 400, 401 | F3: 2 | G3: 324000 | H3: activa | K3: 2026-07-08T09:41:36.289Z
A4: C-027-G1 | B4: C-027 | C4: C | D4: Pecado orginal | E4: 403, 404, 405, 406 | F4: 4 | G4: 269997 | H4: activa | K4: 2026-07-08T10:54:56.925Z
A5: C-028-G1 | B5: C-028 | C5: C | D5: Naturaleza viva | E5: 407, 408, 409 | F5: 3 | G5: 339999 | H5: activa | K5: 2026-07-08T11:04:10.532Z
A6: C-029-G1 | B6: C-029 | C6: C | D6: kundalini | E6: 410, 411 | F6: 2 | G6: 130000 | H6: activa | K6: 2026-07-08T11:09:30.547Z
A7: C-030-G1 | B7: C-030 | C7: C | D7: Lirios del Agua | E7: 412, 413, 414 | F7: 3 | G7: 243001 | H7: activa | K7: 2026-07-08T11:14:28.335Z
A8: C-031-G1 | B8: C-031 | C8: C | D8: Maestros del aire | E8: 415, 416 | F8: 2 | G8: 110000 | H8: activa | K8: 2026-07-08T11:18:51.513Z
A9: C-042-G1 | B9: C-042 | C9: C | D9: Guardianas Gemelas | E9: 467, 468 | F9: 2 | G9: 367500 | H9: archivada | J9: Par para dijes. Ex 'Igualdad Dijes' (#363). | K9: 2026-07-12T01:02:42.515Z
A10: C-042-G2 | B10: C-042 | C10: C | D10: Mellizas del Alba | E10: 469, 470 | F10: 2 | G10: 367500 | H10: archivada | J10: Par para topitos. Ex 'Igualdad Topitos' (#363). | K10: 2026-07-12T01:02:44.192Z

Sheet Proveedores
A1: nombreORazonSocial | B1: nit | C1: cedula | D1: direccion | E1: telefono | F1: email | G1: tipo | H1: notas
A2: Edwin Mauricio Ruiz | C2: 80179071 | D2: carrera6#14-74 Edificio Explinter Oficina 904 | E2: 57 3100000 | F2: gerenciatel@gmail.com | G2: gemas | H2: Proveedor Exclusivo de gemas aliado estrategico
A3: Joyería Artesanal | G3: joyas
A4: Taller de Bronce El Rey, Joyas Artesanales | G4: joyas
A5: Joyería Legado | D5: Bogotá (contacto: Giovanny Ríos) | E5: 3118660925 | G5: insumos

Sheet Clientes
A1: nombre | B1: nit | C1: cedula | D1: direccion | E1: telefono | F1: email | G1: tipo | H1: asesorId
A2: Álvaro Pelaéz | F2: aljop84@gmail.com | G2: embajador | H2: alvaro-pelaez
A3: Ana María Peláez | F3: ana.pelaezc@gmail.com | G3: embajador | H3: ana-maria-pelaez
A4: Andres Agudelo | F4: jesus.agudelo8815@gmail.com | G4: embajador | H4: andres-agudelo
A5: Mauricio Echeverry Naranjo | E5: 3045777537 | F5: mauroverryfire1@gmail.com | G5: embajador | H5: andres-mauricio-echeverry-naranjo
A6: Andrés Mauricio Escobar Ramírez | E6: 3167447931 | F6: cvocmnty@gmail.com | G6: embajador | H6: andres-mauricio-escobar-ramirez
A7: Brenda Gómez | F7: brendiis.gomez@hotmail.com | G7: embajador | H7: brenda-gomez
A8: Carolina Molina | F8: ancamole@gmail.com | G8: embajador | H8: carolina-molina
A9: Comercial Tierra Mädre | F9: comercial.tierramadre@gmail.com | G9: embajador | H9: comercial-tierra-madre
A10: Diana Suárez | F10: dxsuarez87@gmail.com | G10: embajador | H10: diana-suarez
A11: Isa la Negra Vikinga Warrior Portocarrero | E11: 3005271933 | F11: isalavikinga@gmail.com | G11: embajador | H11: isa-la-negra-vikinga-warrior-portocarrero
A12: Jackeline Riascos Urrea | E12: 34 6432159098 | F12: jru2712@gmail.com | G12: embajador | H12: jackeline-riascos-urrea
A13: Jennyfer Florez Ocampo | E13: 3195064211 | F13: jennyferflorezcoach@gmail.com | G13: embajador | H13: jennyfer-florez-ocampo
A14: José Ignacio Florez Ricardo | F14: jflorezricardo@gmail.com | G14: embajador | H14: jose-ignacio-florez-ricardo
A15: Juan Manuel Escobar Ramirez | E15: 3041313637 | F15: juanmanuelescobarco@gmail.com | G15: embajador | H15: juan-manuel-escobar-ramirez
A16: Juan Pablo Loaiza | E16: 3042185582 | F16: bookingradial@gmail.com | G16: embajador | H16: juan-pablo-loaiza
A17: Juliana Forbes | F17: diamanteforbes@gmail.com | G17: embajador | H17: juliana-forbes
A18: Kevin Pineda Perez | E18: 3104149166 | F18: kpp.coomunity@gmail.com | G18: embajador | H18: kevin-pineda-perez
A19: Luis Alfonso Ospina Arias | E19: 3176438744 | F19: lalfonso1713@gmail.com | G19: embajador | H19: luis-alfonso-ospina-arias
A20: Mario Andres Gomez Morales | E20: 3159908888 | F20: magox.coomunity@gmail.com | G20: embajador | H20: mario-andres-gomez-morales
A21: Marsha Jauregui | F21: magnifikesmagnifik@gmail.com | G21: embajador | H21: marsha-jauregui
A22: Martiza campuzano Rodriguez | E22: 3166279999 | F22: seguimientoproduccion1@gmail.com | G22: embajador | H22: martiza-campuzano-rodriguez
A23: Mauricio Ruiz | F23: gerenciatel@gmail.com | G23: embajador | H23: mauricio-ruiz
A24: Migdalia Gomez Serna | E24: 3007669141 | F24: migdaliagomezserna553@gmail.com | G24: embajador | H24: migdalia-gomez-serna
A25: Mitchel Moreno Marin | E25: 3215274171 | F25: mitchellmorenoinvestor@gmail.com | G25: embajador | H25: mitchel-moreno-marin
A26: Olga Lucia Florez Giraldo | E26: 3104101013 | F26: olgaluciafg@gmail.com | G26: embajador | H26: olga-lucia-florez-giraldo
A27: Sebastián Pión | F27: sebastianpion@gmail.com | G27: embajador | H27: sebastian-pion
A28: Tierra Mädre | F28: tierramadre.co@gmail.com | G28: embajador | H28: tierra-madre
A29: Comunicaciones | F29: comunicaciones.tierramadre@gmail.com | G29: embajador | H29: comunicaciones
A30: Valentina Rengifo | F30: valentinarengifo8@gmail.com | G30: embajador | H30: valentina-rengifo

Sheet Ventas
A1: saleId | B1: fechaVenta | C1: itemIdsJoined | D1: clientNombre | E1: precioAcordadoCOP | F1: descuentoCOP | G1: totalCOP | H1: comisionCOP | I1: formaPago | J1: metodoContado | K1: fechaVencimiento | L1: numeroCuotas | M1: carnetUrl | N1: certificadoUrl | O1: estado
A2: VC-0001 | B2: 2026-06-03T00:01:02.912Z | C2: 140 | D2: Mitchel Moreno Marin | E2: 1500000 | F2: 420000 | G2: 1500000 | I2: contado | J2: efectivo | M2: https://drive.google.com/uc?export=view&id=1ZIz5x4B3wXvlm_hl2WtnDL6W7mhMGJrH | O2: confirmada
A3: VC-0004 | B3: 2026-07-02T05:47:51.392Z | C3: 367, 349, 87, 308, 99, 223, 346, 347, 307, 102, 127, 333, 325, 142 | D3: Álvaro Pelaéz | E3: 36587850 | F3: 0 | G3: 36587850 | I3: contado | J3: efectivo | M3: https://drive.google.com/file/d/1zfwGl7NeUgCkbb6CT8QjaRaZi9jnNJOh/view | O3: confirmada
A4: VC-0005 | B4: 2026-07-09T19:05:08.909Z | D4: Juan Pablo Loaiza | E4: 270000 | F4: 0 | G4: 270000 | I4: contado | J4: efectivo | M4: https://drive.google.com/file/d/1aUkGHZqSPBtYUd78v4ksjz3-ulWRm3jS/view | O4: confirmada

Sheet Calidades
A1: Calidad (canónica) | B1: Factor precio | C1: Nota
A2: NO OIL | B2: 1.15
A3: INSIGNIFICANT | B3: 1.2
A4: MINOR | B4: 1.1
A5: F1 | B5: 1
A6: MODERATE | B6: 0.9
A7: F2 | B7: 0.85
A8: FINA SUBLIME | B8: 0.65
A9: FINA ESENCIAL | B9: 0.55
A10: FINA | B10: 0.8
A11: FINA COMERCIAL | B11: 0.45
A12: COMERCIAL SÚPER FINA | B12: 0.4
A13: COMERCIAL FINA | B13: 0.3
... A22: Markup base (TM_MARKUP_DEFAULT) | B22: 3

Sheet Listas
A1: color | B1: calidad | C1: talla | D1: medidas | E1: categoria | F1: ubicacion | G1: estado | H1: coleccion | I1: caja | J1: procedencia | K1: tipoEsmeralda | L1: subtipoForm | M1: tipoJoya | N1: tecnicaJoya | O1: minerales | P1: complementos | Q1: formulaGema | R1: formulaJoya | S1: rangoDescuento | T1: mostrar | U1: escala16 | V1: provTipo | W1: cliTipo | X1: formaPago | Y1: metodoContado | Z1: lotEstado | AA1: saleEstado | AB1: tratamiento
A2: Verde Chivor | B2: NO OIL | C2: 0 | D2: Largo x Ancho | E2: Gema | F2: BOVEDA | G2: DISPONIBLE | H2: Centro del Universo | I2: Legalizada | J2: Boyacá | K2: Muralla | L2: Piedra | M2: Topitos Peq | N2: Engaste | O2: Platino | P2: Diamante | Q2: X1 | R2: X1 | S2: 10% | T2: Sí | U2: 1 | V2: gemas | W2: embajador | X2: contado | Y2: efectivo | Z2: abierto | AA2: reservada | AB2: Ninguno
A3: Verde Azul | B3: INSIGNIFICANT | C3: 5 | D3: Diámetro | E3: Anillo en Plata | F3: OFI.BOGOTA | G3: VENDIDA | H3: Comerciales 29-Ene | I3: Pte Legalizar | J3: Muzo | K3: Piedra Natural | L3: Gema | M3: Topitos Grandes | N3: Microengaste | O3: Oro | P3: Rubí | Q3: X1,5 | R3: X1,1 | S3: 20% | T3: No | U3: 2 | V3: joyas | W3: final | X3: credito | Y3: transferencia | Z3: cerrado | AA3: confirmada | AB3: Aceite
A4: Verde Azuloso | B4: MINOR | C4: 6 | E4: Anillo en Oro | F4: OFI.CALI | G4: ASESOR | H4: Círculos de Poder | I4: Pte Fecha x Legalizar | J4: Chivor | K4: Canutillo | L4: Lote | M4: Topitos Hombre | N4: Filigrana | O4: Oro Rosado | P4: Zafiro | Q4: X2 | R4: X1,2 | S4: 30% | T4: TRUE | U4: 3 | V4: insumos | X4: esmereogenesis | Y4: crypto | Z4: publicado | AA4: cancelada | AB4: Resina
A5: Verde Muzo | B5: F1 | C5: 7 | E5: Aretes | F5: ASESOR | G5: CONSIGNACION | H5: Dinastías | I5: Esmereogenesis | J5: Coscuez | K5: Cola | L5: Joya | M5: Aretes | N5: Fundición | O5: Oro Italiano | P5: Circones (Natural) | Q5: X2,5 | R5: X1,5 | S5: 40% | T5: FALSE | U5: 4 | V5: otros | X5: canje | Z5: cancelado | AB5: Cedar
A6: Verde Vívido | B6: MODERATE | C6: 8 | E6: Topitos | F6: EMBAJADOR | G6: Retornado | H6: Encanto de la Montaña | J6: Gachalá | K6: Raíz | L6: Lote de joyas | M6: Pulsera | N6: Cera perdida | O6: Oro Blanco | P6: Circonia | Q6: X3 | R6: X2 | S6: 50% | U6: 5 | X6: bajo_pedido | Z6: activa | AB6: Estándar
A7: Verde Intenso | B7: F2 | C7: 9 | E7: Pulsera | F7: CLIENTE | G7: ESMEREOGENESIS | H7: Finas 29-Ene | J7: Peñas Blancas | K7: Gema Facetada | L7: Ganga | M7: Dije | N7: Repujado | O7: Oro Negro | P7: Cuarzos | R7: X2,5 | S7: 60% | U7: 6 | X7: consignacion | Z7: archivada | AB7: Natural
A8: Verde Selva | B8: FINA SUBLIME | C8: Baguette | E8: Dije | F8: EN PRODUCCION | G8: ESMERO | H8: Fénix | J8: La Pita | K8: Gola | L8: Macla | M8: Cadena | N8: Calado | O8: Plata 925 | R8: X3 | S8: 70% | AB8: Perma
A9: Verde Natural | B9: FINA ESENCIAL | C9: Brillante | E9: Lote de Gemas | F9: EN CERTIFICACION | G9: DISPONIBLE ADOPTADA | H9: Madres | J9: Quípama | K9: Gola - Murralla | L9: Canutillo | M9: Expansión | N9: Martillado | O9: Plata Rodinada | AB9: Pulida
A10: Verde Limón | B10: FINA | C10: Cabuchon | E10: Joyas | F10: RETORNADO | G10: LOTE X CT | H10: Mariposas de la Montaña | J10: Maripí | K10: Mixto | L10: Insumo | M10: Anillo Mujer | N10: Granulado | O10: Plata China | AB10: Robinada
A11: Verde Viche | B11: FINA COMERCIAL | C11: Canutillo | E11: Piedras | H11: Marketing | J11: Otanche | K11: Murralla + Cristal | L11: Otros | M11: Anillo Hombre | N11: Soldadura | O11: Plata Baño de Oro | AB11: Rodinado
A12: Verde Menta | B12: COMERCIAL SÚPER FINA | C12: Chispero | E12: Dúo Gemas | H12: Princesas | J12: Pauna | K12: Piedra Cristal | L12: LOTE DE JOYAS | M12: Candonga | N12: Electroformado | O12: Bronce | AB12: Variado
A13: Verde Diamantado | B13: COMERCIAL FINA | C13: Chisperito | E13: Gema Facetada | H13: Reinas | J13: San Pablo de Borbur | M13: Set | N13: Alambrado artesanal | O13: Bronce Baño de Oro
A14: Verde Brillante | B14: COMERCIAL SUPERIOR | C14: Corazón | E14: Gemas sueltas | H14: Secretos del Bosque | J14: Yacopí | M14: Choker | N14: Rodinado | O14: Tela
A15: Verde | B15: COMERCIAL ESTÁNDAR | C15: Cuadrada | E15: Gola | H15: Sueños de Mina | J15: Cali | M15: Collar | O15: Hilos
A16: Verde Aguamarina | B16: COMERCIAL | C16: Cushion | E16: Insumo | H16: Terrícolas | J16: Chivor y Muzo | M16: Muralla
A17: Verde claro | B17: Morralla Pulida | C17: En Bruto-Natural | E17: Joya | H17: #4000 | M17: Topitos
A18: Verde Cristal | B18: Morralla Superior | C18: Esmeralda | E18: Joyería Artesanal | H18: 11:11
A19: Verde profundo | B19: Morralla Fina | C19: Gola | E19: Lote Piedras
A20: Verde Turquesa | B20: Morralla Comercial | C20: Iris | E20: Marketing
B21: 1/6 | C21: Lágrima | E21: Muralla
B22: Plata - comercial | C22: Marquis | E22: Otro
B23: Tierra Madre | C23: Marquise | E23: Piedra Cristal
B24: Variada | C24: Morralla-Lapidada | E24: Piedra Natural
C25: Ovalo | E25: Rarezas
C26: Pera | E26: Raíz
C27: Princesa
C28: Rectangular
C29: Redonda
C30: Redonda calibrada
C31: Superman
C32: Trapecio
C33: Trillion
C34: Variado
C35: Varias
C36: Ancestral
C37: Antiguo
C38: Natural
... C40: Semicuadrada
